<?xml version="1.0"?>
<robot xmlns:xacro="http://www.ros.org/wiki/xacro">

    <xacro:include filename="inertial_macros.xacro" />


    <material name="white">
        <color rgba="1 1 1 1"/>
    </material>

    <material name="orange">
        <color rgba="1 0.3 0.1 1"/>
    </material>

    <material name="blue">
        <color rgba="0.2 0.2 1 1"/>
    </material>

    <material name="black">
        <color rgba="0 0 0 1"/>
    </material>



    <link name="base_link">
    
    </link>

    <joint name="chassis_joint" type="fixed">
    <parent link="base_link"/>
    <child link="chassis"/>
    <origin xyz="-0.07 0 0.06"/>
    </joint>

    <link name="chassis">
    <visual>
        <origin xyz="0.28 0 0.41" rpy="0 0 0"/>
        <geometry>
            <cylinder length="0.7" radius="0.275"/>
        </geometry>
        <material name="white"/>
    </visual>
    <collision>
        <origin xyz="0.28 0 0.41" rpy="0 0 0"/>
        <geometry>
            <cylinder length="0.7" radius="0.275"/>
        </geometry>
    </collision>
   <xacro:inertial_cylinder mass="0.1" length="0.7" radius="0.275">
        <origin xyz="0 0 0" rpy="0 0 0"/>
    </xacro:inertial_cylinder>
    </link>

    <gazebo reference="chassis">
    <material>Gazebo/White</material>
    </gazebo>


    <!-- LEFT WHEEL -->

    <joint name="left_wheel_joint" type="continuous">
    <parent link="base_link"/>
    <child link="left_wheel"/>
    <origin xyz="0 0.28 0.06" rpy="-${pi/2} 0 0"/>
    <axis xyz="0 0 1"/>
    </joint>

    <link name="left_wheel">
    <visual>
        <geometry>
            <cylinder length="0.06" radius="0.085" />/>
        </geometry>
        <material name="black"/>
    </visual>
    <collision>
        <geometry>
            <cylinder length="0.06" radius="0.085" />/>
        </geometry>
        <material name="black"/>
    </collision>
    <xacro:inertial_cylinder mass="0.1" length="0.06" radius="0.085">
        <origin xyz="0 0 0" rpy="0 0 0"/>
    </xacro:inertial_cylinder>
    </link>


    <gazebo reference="left_wheel">
    <material>Gazebo/Black</material>
    </gazebo>



    <!-- RIGHT WHEEL -->

    <joint name="right_wheel_joint" type="continuous">
    <parent link="base_link"/>
    <child link="right_wheel"/>
    <origin xyz="0 -0.28 0.06" rpy="${pi/2} 0 0"/>
    <axis xyz="0 0 -1"/>
    </joint>

    <link name="right_wheel">
    <visual>
        <geometry>
            <cylinder length="0.06" radius="0.085" />/>
        </geometry>
        <material name="black"/>
    </visual>
    <collision>
        <geometry>
            <cylinder length="0.06" radius="0.085" />/>
        </geometry>
        <material name="black"/>
    </collision>
    <xacro:inertial_cylinder mass="0.1" length="0.06" radius="0.085">
        <origin xyz="0 0 0" rpy="0 0 0"/>
    </xacro:inertial_cylinder>
    </link>


    <gazebo reference="right_wheel">
    <material>Gazebo/Black</material>
    </gazebo>



    <!-- CASTER WHEEL -->

    <joint name="caster_wheel_joint" type="fixed">
    <parent link="chassis"/>
    <child link="caster_wheel"/>
    <origin xyz="0.45 0 0" rpy="${pi/2} 0 0"/>
    </joint>

    <link name="caster_wheel">
    <visual>
        <geometry>
            <cylinder length="0.04" radius="0.065" />/>
        </geometry>
        <material name="blue"/>
    </visual>
    <collision>
        <geometry>
            <cylinder length="0.04" radius="0.065" />/>
        </geometry>
        <material name="blue"/>
    </collision>
    <xacro:inertial_cylinder mass="0.1" length="0.04" radius="0.065">
        <origin xyz="0 0 0" rpy="0 0 0"/>
    </xacro:inertial_cylinder>
    </link>


    <gazebo reference="caster_wheel">
        <material>Gazebo/Blue</material>
        <mu1 value="0.001"/>
        <mu2 value="0.001"/>
    </gazebo>



</robot>